Workbook
Name _: #REF!
Name _A100006: #REF!
Name _Key1: '[1]BASE DE DATOS'!$A$250:$A$258
Name _Order1: 255
Name _Order2: 255
Name _Sort: '[1]BASE DE DATOS'!$A$248:$C$256
Name _TOT126: #REF!
Name A: '[2]TABLA AMORTIZACIÓN'!$D$12
Name A_1: #REF!
Name A_2: #REF!
Name A_3: #REF!
Name A_4: #REF!
Name abriendo: '[3]FORMATO LIMPIO'!$F$180
Name acces: #REF!
Name ACTIVAR: '[3]FORMATO LIMPIO'!$A$190
Name Acto: #REF!
Name Acto_inseguro: #REF!
Name Actualiza: #REF!
Name ACTUALIZACION: #REF!
Name ad: #REF!
Name ADMINISTRACION: '[4]3_ANALISIS_A'!$E$63
Name Agente_causante: #REF!
Name aguasjugos: #REF!
Name alcance: #REF!
Name ANEXOS: #REF!
Name Anio: [5]paramentros!$H$6:$H$12
Name AntBD: [6]BD!$K$2:$K$603
Name años: #REF!
Name Apellido: '[7]BD SNC ST)'!$N$2:$N$3003
Name Area: #REF!
Name AreBD: [6]BD!$F$2:$F$603
Name as: #REF!
Name Ass: [8]VALORACIÓN!$G$2:$G$3
Name autonomas: #REF!
Name Avance_de_la_acción_en: #REF!
Name B: #REF!
Name base: '[1]BASE DE DATOS'!$B$6:$D$39
Name basedatos: '[1]BASE DE DATOS'!$B$6:$D$39
Name BORDER: #REF!
Name borrar: #REF!
Name bu: _F3C4
Name buscaR: _F3C4
Name cal: #REF!
Name CAPACITACIONES: #REF!
Name Cargo: #REF!
Name Cargo_origen: #REF!
Name cargos: #REF!
Name cat: [9]Hoja2!$A$2:$A$9
Name categoria: #REF!
Name causa: #REF!
Name ccc: #REF!
Name cd: #REF!
Name ced: [10]valoracion!$B$64:$B$67
Name certificaciones_ISO: #REF!
Name CERTIFICADOS: #REF!
Name ciu: #REF!
Name ciudad: #REF!
Name codcargo: #REF!
Name Codigos: [11]!Productos[CÓDIGO]
Name COMPLEMENTAR_EL_PROYECTO_SAP7R3_EN_TODAS_LAS_PLANTAS: #REF!

Sheet DATOS INICIALES
B2: CLIENTE | D2: Chip Station HONGO - DUCTOS - CAMPANAS
B4: FECHA ENVÍO PROPUESTA
B6: HORARIO PERMITIDO | D6: Diurno
B8: SISO ASIGNADO | D8: 0
B10: EQUIPOS A INTERVENIR
B12: Tipo de Precipitador | C12: Cantidad de Equipos | D12: Total Celdas Equivalentes | E12: Acceso | F12: Frecuencia | H12: Campana (2x1x0.6 m) | I12: Frecuencia Campana | J12: Acceso Campana
B13: Sencillo | C13: 0 | D13: =C13*1 -> 0 | E13: Andamio | F13: Bimestral | H13: 2 | I13: Semestral | J13: Escalera
B14: Doble | C14: 0 | D14: =C14*2 -> 0 | H14: Número de camapanas
B15: Triple | C15: 0 | D15: =C15*3 -> 0
B16: Total Equivalentes | D16: =SUM(D13:D15) -> 0
B18: Tipo de Ventilador | C18: Cantidad | D18: Fercuencia Ventilador | E18: Acceso | F18: Dificultad | H18: Ducto (0.35x0.35x2) m | I18: Frecuencia Ducto | J18: Acceso Ducto
B19: Motor con flujo interno | C19: 1 | D19: semestral | E19: Andamio 140 x 74 dos cuerpos de 2m | H19: 2 | I19: Semestral | J19: Escalera
B20: Motor con fjujo externo | C20: 0
B21: Total Ventiladores | C21: =SUM(C19:C20) -> 1 | H21: =+(0.35+0.35+0.35+0.35)*2 -> 2.8 | I21: m2
H22: =+(0.76+0.76+0.76+0.76)*60 -> 182.4 | I22: m2
B23: Otros Costos | H23: =+H22/H21 -> 65.142857 | I23: Tramos de ducto equivalentes
B24: Nombre repuesto o material o servicio | C24: Cantidad | D24: Unidad | E24: Costo | F24: Proveedor
B25: Bandas | C25: 1 | D25: Unidad | E25: 35000
D26: Unidad
D27: Unidad
D28: Unidad
D29: Unidad
D30: Total | E30: =SUM(E25:E29) -> 35000

Sheet DATA PERSONAL
A1: SALARIOS
A2: Nivel | B2: Nómina | C2: Aux. Transporte | D2: Rodamiento | E2: Subtotal | F2: COSTO DIA | G2: COSTO HORA | H2: Fecha del Dato
A3: Operario 1 | B3: 2000000 | C3: 200000 | D3: 100000 | E3: =SUM(B3:D3) -> 2300000 | F3: =E3/B71 -> 129577.46 | G3: =F3/7.2 -> 17996.87 | H3: 45848
A4: Operario 2 | B4: 1600000 | C4: 200000 | D4: 100000 | E4: =SUM(B4:D4) -> 1900000 | F4: =E4/B71 -> 107042.25 | G4: =F4/7.2 -> 14866.98 | H4: 45848
A5: Ingeniero | B5: 4000000 | C5: 200000 | D5: 200000 | E5: =SUM(B5:D5) -> 4400000 | F5: =E5/B71 -> 247887.32 | G5: =F5/7.2 -> 34428.795 | H5: 45848
A9: CURSOS Y EXAMENES OPERARIOS E INGENIEROS
A10: Descripción Curso o Examen | B10: Tipo Elemento | C10: Und. Medida | D10: Factor de Uso / Meses Depreciación | E10: COSTO UNITARIO | F10: COSTO MENSUAL | G10: COSTO HORA | H10: Fecha del Dato
A11: Trabajo en alturas | B11: Curso | C11: Und | D11: 18 | E11: 120000 | F11: =E11/D11 -> 6666.6667 | G11: =(F11/B$71)/7.2 -> 52.164841 | H11: 45848
A12: coordinador en alturas | B12: Curso | C12: Und | D12: 36 | E12: 800000 | F12: =E12/D12 -> 22222.222 | G12: =(F12/B$71)/7.2 -> 173.8828 | H12: 45848
A13: EMO | B13: Exámen | C13: Und | D13: 18 | E13: 150000 | F13: =E13/D13 -> 8333.3333 | G13: =(F13/B$71)/7.2 -> 65.206051 | H13: 45848
F14: =SUM(F11:F13) -> 37222.222 | G14: =SUM(G11:G13) -> 291.2537
A16: DOTACIÓN Y E.P.P. CLASE 1
A17: Descripción Elemento | B17: Tipo Elemento | C17: Factor de Uso / Meses Depreciación | D17: Cantidad por Vigencia | E17: COSTO UNITARIO | F17: COSTO MENSUAL | G17: COSTO HORA | H17: Fecha del Dato
A18: Guantes de vaqueta | B18: E.P.P. | C18: 1 | D18: 1 | E18: 20000 | F18: =E18/C18*D18 -> 20000 | G18: =(F18/B$71)/7.2 -> 156.49452 | H18: 45848
A19: Guantes de soldador | B19: E.P.P. | C19: 2 | D19: 1 | E19: 70000 | F19: =E19/C19*D19 -> 35000 | G19: =(F19/B$71)/7.2 -> 273.86541 | H19: 45848
A20: Careta de soldadura | B20: E.P.P. | C20: 12 | D20: 1 | E20: 220000 | F20: =E20/C20*D20 -> 18333.333 | G20: =(F20/B$71)/7.2 -> 143.45331 | H20: 45848
A21: Respirador | B21: E.P.P. | C21: 3 | D21: 1 | E21: 30000 | F21: =E21/C21*D21 -> 10000 | G21: =(F21/B$71)/7.2 -> 78.247261 | H21: 45848
A22: Lentes de seguridad | B22: E.P.P. | C22: 1 | D22: 1 | E22: 15000 | F22: =E22/C22*D22 -> 15000 | G22: =(F22/B$71)/7.2 -> 117.37089 | H22: 45848
A23: Botas de seguridad | B23: E.P.P. | C23: 12 | D23: 1 | E23: 135000 | F23: =E23/C23*D23 -> 11250 | G23: =(F23/B$71)/7.2 -> 88.028169 | H23: 45848
A24: Arnés | B24: E.P.P. | C24: =12*7 -> 84 | D24: 1 | E24: 355000 | F24: =E24/C24*D24 -> 4226.1905 | G24: =(F24/B$71)/7.2 -> 33.068783 | H24: 45848
A25: Línea de vida | B25: E.P.P. | C25: 84 | D25: 1 | E25: 270000 | F25: =E25/C25*D25 -> 3214.2857 | G25: =(F25/B$71)/7.2 -> 25.150905 | H25: 45848
A26: Jean | B26: Dotación | C26: 12 | D26: 3 | E26: 45000 | F26: =E26/C26*D26 -> 11250 | G26: =(F27/B$71)/7.2 -> 88.028169 | H26: 45848
A27: Camisa | B27: Dotación | C27: 12 | D27: 3 | E27: 45000 | F27: =E27/C27*D27 -> 11250 | G27: =(F27/B$71)/7.2 -> 88.028169 | H27: 45848
A28: Casco | B28: E.P.P. | C28: 24 | D28: 1 | E28: 68000 | F28: =E28/C28*D28 -> 2833.3333 | G28: =(F28/B$71)/7.2 -> 22.170057 | H28: 45848
F29: =SUM(F18:F28) -> 142357.14 | G29: =SUM(G18:G28) -> 1113.9057
A31: KIT DE HERRAMIENTA PERSONAL CLASE 1 | C31: DESCRIPCIÓN CLASE:
A32: Descripción Herramienta Personal | B32: Tipo Elemento | C32: Factor de Uso / Meses Depreciación | D32: Cantidad por Vigencia | E32: COSTO UNITARIO | F32: MANTENIMIENTO | G32: COSTO MENSUAL | H32: COSTO HORA | I32: Fecha del Dato
A33: Rotomartillo | B33: Herr. de Trabajo | C33: 36 | D33: 1 | E33: 1100000 | F33: 250000 | G33: =(E33+F33)/C33 -> 37500 | H33: =(G33/B$71)/7.2 -> 293.42723 | I33: 45659
A34: Taladro lámina | B34: Herr. de Trabajo | C34: 36 | D34: 1 | E34: 395000 | F34: 250000 | G34: =(E34+F34)/C34 -> 17916.667 | H34: =(G34/B$71)/7.2 -> 140.19301 | I34: 45659
A35: Pulidora | B35: Herr. de Trabajo | C35: 36 | D35: 1 | E35: 495000 | F35: 250000 | G35: =(E35+F35)/C35 -> 20694.444 | H35: =(G35/B$71)/7.2 -> 161.92836 | I35: 45659
A36: Almadana | B36: Herr. de Trabajo | C36: 25 | D36: 1 | E36: 65000 | F36: 250000 | G36: =(E36+F36)/C36 -> 12600 | H36: =(G36/B$71)/7.2 -> 98.591549 | I36: 45659
A37: Martillo | B37: Herr. de Trabajo | C37: 12 | D37: 1 | E37: 25000 | G37: =(E37+F37)/C37 -> 2083.3333 | H37: =(G37/B$71)/7.2 -> 16.301513 | I37: 45659
A38: Equipo de soldadura | B38: Herr. de Trabajo | C38: 60 | D38: 1 | E38: 900000 | F38: 380000 | G38: =(E38+F38)/C38 -> 21333.333 | H38: =(G38/B$71)/7.2 -> 166.92749 | I38: 45659
A39: Destornilaldor estrella | B39: Herr. de Trabajo | C39: 12 | D39: 3 | E39: 4000 | G39: =(E39+F39)/C39 -> 333.33333 | H39: =(G39/B$71)/7.2 -> 2.608242 | I39: 45659
A40: Destornilllador pala | B40: Herr. de Trabajo | C40: 12 | D40: 3 | E40: 5000 | G40: =(E40+F40)/C40 -> 416.66667 | H40: =(G40/B$71)/7.2 -> 3.2603026 | I40: 45659
A41: Llave expansión | B41: Herr. de Trabajo | C41: 36 | D41: 3 | E41: 17000 | G41: =(E41+F41)/C41 -> 472.22222 | H41: =(G41/B$71)/7.2 -> 3.6950096 | I41: 45659
A42: Nivel | B42: Herr. de Trabajo | C42: 36 | D42: 1 | E42: 12000 | G42: =(E42+F42)/C42 -> 333.33333 | H42: =(G42/B$71)/7.2 -> 2.608242 | I42: 45659
A43: Espatula | B43: Herr. de Trabajo | C43: 3 | D43: 1 | E43: 5000 | G43: =(E43+F43)/C43 -> 1666.6667 | H43: =(G43/B$71)/7.2 -> 13.04121 | I43: 45659
A44: Hombresolo | B44: Herr. de Trabajo | C44: 25 | D44: 1 | E44: 30000 | G44: =(E44+F44)/C44 -> 1200 | H44: =(G44/B$71)/7.2 -> 9.3896714 | I44: 45659
A45: Pistola de silicona | B45: Herr. de Trabajo | C45: 12 | D45: 1 | E45: 37000 | G45: =(E45+F45)/C45 -> 3083.3333 | H45: =(G45/B$71)/7.2 -> 24.126239 | I45: 45659
...

Sheet SALARIOS
B1: MANO DE OBRA PERSONAL EJECUTOR
E3: Valor tiempo Diurno | K3: Prestaciones | P3: Concepto | Q3: % Equivalente
B4: Empleado | C4: Salario día | D4: Valor Hora | E4: Precipitador | F4: Ventilador | G4: Camapana | H4: Ducto | J4: Empleado | K4: Precipitador | L4: Ventilador | M4: Camapana | N4: Ducto | P4: Salud Pensión Empresa | Q4: 0.2
B5: Operario 1 | C5: =+'DATA PERSONAL'!F3+('DATA PERSONAL'!G14*7.2)+('DATA PERSONAL'!H52*7.2) -> 140657.15 | D5: =+C5/7.2 -> 19535.716 | E5: =$D$5*C20 -> 0 | F5: =$D$5*D20 -> 97678.578 | G5: =$D$5*E20 -> 97678.578 | H5: =$D$5*F20 -> 97678.578 | J5: Operario 1 | K5: =+(E5+E11)*$Q$11 -> 0 | L5: =+(F5+F11)*$Q$11 -> 48468.11 | M5: =+(G5+G11)*$Q$11 -> 48468.11 | N5: =+(H5+H11)*$Q$11 -> 48468.11 | P5: Salud Pensión empleado | Q5: -0.08
B6: Operario 2 | C6: =+'DATA PERSONAL'!F4+('DATA PERSONAL'!G14*7.2)+('DATA PERSONAL'!H52*7.2) -> 118121.94 | D6: =+C6/7.2 -> 16405.825 | E6: =$D$6*C21 -> 0 | F6: =$D$6*D21 -> 0 | G6: =$D$6*E21 -> 0 | H6: =$D$6*F21 -> 0 | J6: Operario 2 | K6: =+(E6+E12)*$Q$11 -> 0 | L6: =+(F6+F12)*$Q$11 -> 0 | M6: =+(G6+G12)*$Q$11 -> 0 | N6: =+(H6+H12)*$Q$11 -> 0 | P6: ARL Empresa R5 | Q6: 0.0696
B7: Coordinador | C7: =+'DATA PERSONAL'!F5+('DATA PERSONAL'!G14*7.2)+('DATA PERSONAL'!H52*7.2) -> 258967.01 | D7: =+C7/7.2 -> 35967.64 | E7: =$D$7*C22 -> 0 | F7: =$D$7*D22 -> 0 | G7: =$D$7*E22 -> 0 | H7: =$D$7*F22 -> 0 | J7: Coordinador | K7: =+(E7+E13)*$Q$11 -> 0 | L7: =+(F7+F13)*$Q$11 -> 0 | M7: =+(G7+G13)*$Q$11 -> 0 | N7: =+(H7+H13)*$Q$11 -> 0 | P7: Caja de compensación | Q7: 0.04
P8: Cesantías | Q8: 0.0833
E9: Valor Recaregto Nocturno | K9: TOTALES | P9: Interés Cesantías | Q9: 0.1
B10: Empleado | C10: Salario día | D10: Valor Hora | E10: Precipitador | F10: Ventilador | G10: Camapana | H10: Ducto | J10: Empleado | K10: Precipitador | L10: Ventilador | M10: Camapana | N10: Ducto | P10: Prima | Q10: 0.0833
B11: Operario 1 | C11: =+C5+('DATA PERSONAL'!G14*7.2)+('DATA PERSONAL'!H52*7.2) -> 151736.84 | D11: =+C11/7.2 -> 21074.561 | E11: =$D$11*$Q$13*G20 -> 0 | F11: =$D$11*$Q$13*H20 -> 0 | G11: =$D$11*$Q$13*I20 -> 0 | H11: =$D$11*$Q$13*J20 -> 0 | J11: Operario 1 | K11: =+E5+E11+K5 -> 0 | L11: =+F5+F11+L5 -> 146146.69 | M11: =+G5+G11+M5 -> 146146.69 | N11: =+H5+H11+N5 -> 146146.69 | P11: Total | Q11: =SUM(Q4:Q10) -> 0.4962
B12: Operario 2 | C12: =+C6+('DATA PERSONAL'!G14*7.2)+('DATA PERSONAL'!H52*7.2) -> 129201.63 | D12: =+C12/7.2 -> 17944.67 | E12: =$D$12*$Q$13*G21 -> 0 | F12: =$D$12*$Q$13*H21 -> 0 | G12: =$D$12*$Q$13*I21 -> 0 | H12: =$D$12*$Q$13*J21 -> 0 | J12: Operario 2 | K12: =+E6+E12+K6 -> 0 | L12: =+F6+F12+L6 -> 0 | M12: =+G6+G12+M6 -> 0 | N12: =+H6+H12+N6 -> 0
B13: Coordinador | C13: =+C7+('DATA PERSONAL'!G14*7.2)+('DATA PERSONAL'!H52*7.2) -> 270046.7 | D13: =+C13/7.2 -> 37506.486 | E13: =$D$13*$Q$13*G22 -> 0 | F13: =$D$13*$Q$13*H22 -> 0 | G13: =$D$13*$Q$13*I22 -> 0 | H13: =$D$13*$Q$13*J22 -> 0 | J13: Coordinador | K13: =+E7+E13+K7 -> 0 | L13: =+F7+F13+L7 -> 0 | M13: =+G7+G13+M7 -> 0 | N13: =+H7+H13+N7 -> 0 | P13: Recargo nocturno | Q13: 1.35
B14: Tener en cuenta tiempo de trabajo y de desplazamientos
C18: HORAS DIURNAS | G18: HORAS NOCTURNAS | L18: DIAS
C19: precipitador | D19: ventilador | E19: campana | F19: ducto | G19: precipitador | H19: ventilador | I19: campana | J19: ducto | K19: TOTAL
B20: Operario 1 | D20: 5 | E20: 5 | F20: 5 | K20: =SUM(C20:J20) -> 15 | L20: =+K20/7.2 -> 2.0833333
B21: Operario 2 | K21: =SUM(C21:J21) -> 0 | L21: =+K21/7.2 -> 0
B22: Coordinador | K22: =SUM(C22:J22) -> 0 | L22: =+K22/7.2 -> 0
B23: Totales | C23: =SUM(C20:C22) -> 0 | D23: =SUM(D20:D22) -> 5 | E23: =SUM(E20:E22) -> 5 | F23: =SUM(F20:F22) -> 5 | G23: =SUM(G20:G22) -> 0 | H23: =SUM(H20:H22) -> 0 | I23: =SUM(I20:I22) -> 0 | J23: =SUM(J20:J22) -> 0

Sheet TRANSPORTES
A1: COSTOS POR TRANSPORTES / ALQUILER DE HERRAMIENTAS / RODAMIENTOS
A3: Andamio/día | B3: 60000 | D3: Transporte de Insumos y celdas | E3: 2 | G3: ¿Se Alquila Andamio? | H3: no | J3: ¿Se Alquila Escalera ? | K3: no | M3: Rodamiento/ operarios | N3: 6000
A4: Días Andamio | B4: 0 | D4: Costo Transporte de insumos área metropolitana | E4: 70000 | G4: trayectos | H4: 2 | J4: trayectos | K4: 2 | M4: trayectos | N4: 3
A5: total Andamio | B5: =+B3*B4 -> 0 | D5: Costo Total transporte de insumos | E5: =+E3*E4 -> 140000 | G5: Costo Transporte | H5: 90000 | J5: Costo Transporte | K5: 90000 | M5: Total Rodamientos | N5: =N3*N4 -> 18000
G6: Costo transporte Andamio | H6: =IF(H3="si",H4*H5,0) -> 0 | J6: Costo por Escalera | K6: =IF(K3="si",K4*K5,0) -> 0
A7: Escalera/día | B7: 15000 | D7: Transporte de Insumos y celdas | E7: 0 | M7: Parqueadero | N7: 12000
A8: Días Escalera | B8: 0 | D8: Costo Transporte de insumos Rionegro | E8: 90000 | M8: Cantidad | N8: 3
A9: total Escalera | B9: =+B7*B8 -> 0 | D9: Costo Total transporte de insumos | E9: =(E8)*E7 -> 0 | M9: Total Rodamientos | N9: =N7*N8 -> 36000
A10: Costo Arriendo Equipos | B10: =+B5+B9 -> 0 | D10: Costo Total transporte de insumos | E10: =+E5+H6+K6+N5+E9+N9 -> 194000
A14: si
A15: no
A36: ecovivir2023

Sheet DATOS INSU
A1: COSTOS POR INSUMOS
A2: DATOS INSUMOS PRECIPITADORES
A4: Insumo | B4: Contenido por unidad | C4: Unidad de medida | D4: Costo/unidad | E4: Costo/Unidad medida | F4: Unidad de Medida (costo) | G4: Fecha Actualización
A5: Desincrustante | B5: 19 | C5: L | D5: 277999 | E5: =+D5/B5 -> 14631.526 | F5: $/L | G5: 45814
A6: Desengrasante Behrlan | B6: 19 | C6: L | D6: 125302 | E6: =+D6/B6 -> 6594.8421 | F6: $/L | G6: 45814
A7: Estopa Fina | B7: 10 | C7: Kg | D7: 135000 | E7: =D7/B7 -> 13500 | F7: $/Kg | G7: 45814
A8: Estopa Normal | B8: 1 | C8: kg | D8: 8000 | E8: =D8/B8 -> 8000 | F8: $/Kg | G8: 45814
A9: Toalla Cocina Pacx6Rollos | B9: 6 | C9: Rollo | D9: 89672.45 | E9: =D9/B9 -> 14945.408 | F9: $/Rollo | G9: 45814 | I9: =237000/20 -> 11850 | J9: =+I9*1.5 -> 17775
A10: Toalla Cocina Pacx3Rollos | B10: 3 | C10: Rollo | D10: 65450 | E10: =D10/B10 -> 21816.667 | F10: $/Rollo | G10: 45814
A11: Esponjas de alambre | B11: 1 | C11: Un | D11: 650 | E11: =D11/B11 -> 650 | F11: $/Unidad | G11: 45918
A12: Bolsa Negra Pacx50 | B12: 50 | C12: Paquete | D12: 25600 | E12: =D12/B12 -> 512 | F12: $/Bolsa | G12: 45918
A14: CONSUMOS Y COSTOS POR PRECIPITADORES
A16: Insumo | B16: Consumo promedio por Celda/equipo | C16: unidad de medida (consumo) | D16: Factor de Seguridad | E16: Consumo total / Celdas /o equipos | F16: Consumo /Rutina | G16: Unidad de medida | H16: Cotos por Insumo/Rutina
A17: Desengrasante Hornos | B17: 0.67 | C17: L/celda | D17: 0.2 | E17: ='DATOS INICIALES'!$D$16*B17 -> 0 | F17: =E17*(1+D17) -> 0 | G17: Kg/Celdas | H17: =F17*E5 -> 0
A18: Desengrasante Behrlan | B18: 0.2 | C18: L/Equipo | D18: 0.2 | E18: ='DATOS INICIALES'!$D$16*B18 -> 0 | F18: =E18*(1+D18) -> 0 | G18: L/Equipo | H18: =F18*E6 -> 0
A19: Estopa Normal | B19: 0.2 | C19: kg/celda | D19: 0.2 | E19: ='DATOS INICIALES'!$D$16*B19 -> 0 | F19: =E19*(1+D19) -> 0 | G19: Kg/Equipo | H19: =F19*E8 -> 0
A20: Esponjas de alambre | B20: 1 | C20: Un | D20: 0.2 | E20: ='DATOS INICIALES'!$D$16*B20 -> 0 | F20: =E20*(1+D20) -> 0 | G20: Unidad/Equipo | H20: =F20*E9 -> 0
A21: Bolsa Basura Pacx50 | B21: 1 | C21: Paquete/celda | D21: 0.2 | E21: ='DATOS INICIALES'!$D$16*B21 -> 0 | F21: =E21*(1+D21) -> 0 | G21: Bolsa/Equipo | H21: =F21*E12 -> 0
A22: Total | H22: =SUM(H17:H21) -> 0
A24: DATOS INSUMOS VENTILADORES
A26: Insumo | B26: Contenido por unidad | C26: Unidad de medida | D26: Costo/unidad | E26: Costo/Unidad medida | F26: Unidad de Medida (costo) | G26: Fecha Actualización
A27: Estopa Normal | B27: 1 | C27: kg | D27: =D8 -> 8000 | E27: =D27/B27 -> 8000 | F27: $/Kilo | G27: =+G8 -> 45814
A28: Desengrasante Hornos | B28: 5.6 | C28: kg | D28: =D6 -> 125302 | E28: =D28/B28 -> 22375.357 | F28: $/Kilo | G28: =+G6 -> 45814
A29: Esponjas de alambre | B29: 1 | C29: Un | D29: =D11 -> 650 | E29: =D29/B29 -> 650 | F29: =G20 -> Unidad/Equipo | G29: 45919
A30: Grasa lubricacion | B30: 400 | C30: Gramos/tubo | D30: 34000 | E30: =D30/B30 -> 85 | F30: $/gramo
A32: CONSUMO Y COSTOS VENTILADORES
A34: Insumo | B34: Consumo promedio por ventilador | C34: unidad de medida (consumo) | D34: Factor de Seguridad | E34: Consumo total | F34: Consumo /Rutina | G34: Unidad de medida | H34: Cotos por Insumo/Rutina
A35: Estopa Normal | B35: 1 | C35: kg/ventila | D35: 0.2 | E35: ='DATOS INICIALES'!$C$21*B35 -> 1 | F35: =E35*(1+D35) -> 1.2 | G35: Kg/Equipo | H35: =F35*E27 -> 9600
A36: Desengrasante Hornos | B36: 1 | C36: Litro/ventila | D36: 0.2 | E36: ='DATOS INICIALES'!$C$21*B36 -> 1 | F36: =E36*(1+D36) -> 1.2 | G36: Kg/Equipo | H36: =F36*E28 -> 26850.429
A37: Esponjas de alambre | B37: 1 | C37: Un | D37: 0.2 | E37: ='DATOS INICIALES'!$C$21*B37 -> 1 | F37: =E37*(1+D37) -> 1.2 | G37: Unidad/Equipo
A38: Grasa lubricacion | B38: 80 | C38: Tubo/Ventila | D38: 0.2 | E38: ='DATOS INICIALES'!$C$21*B38 -> 80 | F38: =E38*(1+D38) -> 96 | G38: g/Equipo | H38: =F38*E30 -> 8160
A39: Total | H39: =SUM(H34:H38) -> 44610.429
A41: DATOS INSUMOS CAMPANAS
A43: Insumo | B43: Contenido por unidad | C43: Unidad de medida | D43: Costo/unidad | E43: Costo/Unidad medida | F43: Unidad de Medida (costo) | G43: Fecha Actualización
A44: Estopa Normal | B44: =+B8 -> 1 | C44: kg | D44: =+D8 -> 8000 | E44: =+D44/B44 -> 8000 | F44: $/Kilo | G44: =+G8 -> 45814
B45: 0 | C45: Litros | D45: 31900 | E45: =+D45/B45 -> #DIV/0! | F45: $/Litro
A46: Desengrasante Behrlan | B46: =+B6 -> 19 | C46: L | D46: =+D6 -> 125302 | E46: =+D46/B46 -> 6594.8421 | F46: $/L | G46: =+G6 -> 45814
A48: CONSUMO Y COSTOS CAMPANAS
A50: Insumo | B50: Consumo promedio campana (2x1x0.6) m | C50: unidad de medida (consumo) | D50: Factor de Seguridad | E50: Consumo total | F50: Consumo /Rutina | G50: Unidad de medida | H50: Cotos por Insumo/Rutina | I50: Veces Equivalentes para un Campana de (2 x 1 x 0,6) m
A51: Estopa Normal | B51: 0.5 | C51: kg/celda | D51: 0.2 | E51: =+'DATOS INICIALES'!H13*B51 -> 1 | F51: =E51*(1+D51) -> 1.2 | G51: Kg/Equipo | H51: =+F51*E44 -> 9600
...

Sheet MATRIZ VENTA
B2: MATRIZ DE VENTA PRECIPITADOR | D2: =IF('DATOS INICIALES'!D2="","",'DATOS INICIALES'!D2) -> Chip Station HONGO - DUCTOS - CAMPANAS
B3: Descripción | C3: Costos
B4: Mano de obra | C4: Carga Salarial operativa | E4: =SALARIOS!K11+SALARIOS!K12 -> 0
C5: Carga Salarial coordinador | E5: =SALARIOS!K13 -> 0
B7: Insumos | E7: ='DATOS INSU'!H22 -> 0
B8: Recursos para lavado de celdas | E8: ='DATOS INSU'!J72 -> 0
B9: Imprevistos | C9: Otros | E9: =SUM(E3:E8)*5% -> 0
B10: * Gastos fijos | C10: Otros | E10: =SUM(E4:E9)*5% -> 0
B11: TOTAL | E11: =SUM(E4:E10) -> 0
B14: MATRIZ DE VENTA VENTILADOR | D14: =+D2 -> Chip Station HONGO - DUCTOS - CAMPANAS
B15: Descripción | C15: Costos
B16: Mano de obra | C16: Carga Salarial operativa | E16: =SALARIOS!L11+SALARIOS!L12 -> 146146.69
C17: Carga Salarial coordinador | E17: =SALARIOS!L13 -> 0
B19: Insumos | E19: ='DATOS INSU'!H39 -> 44610.429
B20: Imprevistos | C20: Otros | E20: =SUM(E15:E19)*5% -> 9537.8558
B21: * Gastos fijos | C21: Otros | E21: =SUM(E16:E20)*5% -> 10014.749
B22: TOTAL | E22: =SUM(E16:E21) -> 210309.72
B25: MATRIZ DE VENTA CAMPANA | D25: =+D2 -> Chip Station HONGO - DUCTOS - CAMPANAS
B26: Descripción | C26: Costos
B27: Mano de obra | C27: Carga Salarial operativa | E27: =SALARIOS!M11+SALARIOS!M12 -> 146146.69
C28: Carga Salarial coordinador | E28: =SALARIOS!M13 -> 0
B30: Insumos | E30: ='DATOS INSU'!H54 -> 33341.432
B31: Imprevistos | C31: Otros | E31: =SUM(E26:E30)*5% -> 8974.406
B32: * Gastos fijos | C32: Otros | E32: =SUM(E27:E31)*5% -> 9423.1263
B33: TOTAL | E33: =SUM(E27:E32) -> 197885.65
B36: MATRIZ DE VENTA DUCTO | D36: =+D2 -> Chip Station HONGO - DUCTOS - CAMPANAS
B37: Descripción | C37: Costos
B38: Mano de obra | C38: Carga Salarial operativa | E38: =SALARIOS!N11+SALARIOS!N12 -> 146146.69
C39: Carga Salarial coordinador | E39: =SALARIOS!N13 -> 0
B41: Insumos | E41: ='DATOS INSU'!H62 -> 33341.432
B42: Imprevistos | C42: Otros | E42: =SUM(E37:E41)*5% -> 8974.406
B43: * Gastos fijos | C43: Otros | E43: =SUM(E38:E42)*5% -> 9423.1263
B44: TOTAL | E44: =SUM(E38:E43) -> 197885.65
B47: MATRIZ DE SST Y LOGISTICA Y TRANSPORTE | D47: =+D2 -> Chip Station HONGO - DUCTOS - CAMPANAS
B48: Descripción | C48: Costos | E48: 0.05
B49: SST | C49: ='DATOS INICIALES'!D8 -> 0 | E49: =C49*(1+$E$48) -> 0
B50: Transporte | C50: =TRANSPORTES!E10+TRANSPORTES!B10 -> 194000 | E50: =C50*(1+$E$48) -> 203700
B51: Otros costos | C51: ='DATOS INICIALES'!E30 -> 35000 | E51: =C51*(1+$E$48) -> 36750
B52: * Gastos fijos | E52: =SUM(E49:E51)*E48 -> 12022.5
B53: TOTAL | E53: =SUM(E49:E51)+E52 -> 252472.5

Sheet Oferta
B4: DESCRIPCIÓN | C4: CANT | D4: UN | E4: V/R UNITARIO COP | F4: V/R TOTAL COP | G4: COSTO | H4: VENTA | I4: UTILIDAD | J4: %
B5: Mantenimiento preventivo para precipitador electrostático | C5: =SUM('DATOS INICIALES'!C13:C15) -> 0 | D5: UND | E5: =IFERROR(F5/C5,0) -> 0 | F5: =+H5 -> 0 | G5: ='MATRIZ VENTA'!$E$11 -> 0 | H5: =+G5/(1-J5) -> 0 | I5: =H5-G5 -> 0 | J5: 0.25
B6: Mantenimiento preventivo para ventilador | C6: =+'DATOS INICIALES'!C21 -> 1 | D6: UND | E6: =IFERROR(F6/C6,0) -> 323553.42 | F6: =+H6 -> 323553.42 | G6: ='MATRIZ VENTA'!$E$22 -> 210309.72 | H6: =+G6/(1-J6) -> 323553.42 | I6: =H6-G6 -> 113243.7 | J6: 0.35
B7: Mantenimiento preventivo para campana | C7: =+'DATOS INICIALES'!H13 -> 2 | D7: UND | E7: =IFERROR(F7/C7,0) -> 141346.89 | F7: =+H7 -> 282693.79 | G7: ='MATRIZ VENTA'!$E$33 -> 197885.65 | H7: =+G7/(1-J7) -> 282693.79 | I7: =H7-G7 -> 84808.136 | J7: 0.3
B8: Mantenimiento preventivo para ducto | C8: =+'DATOS INICIALES'!H19 -> 2 | D8: ML | E8: =IFERROR(F8/C8,0) -> 152219.73 | F8: =+H8 -> 304439.46 | G8: ='MATRIZ VENTA'!$E$44 -> 197885.65 | H8: =+G8/(1-J8) -> 304439.46 | I8: =H8-G8 -> 106553.81 | J8: 0.35
B9: SST | C9: 1 | D9: UND | E9: =+F9/C9 -> 0 | F9: =+H9 -> 0 | G9: =+'MATRIZ VENTA'!E49 -> 0 | H9: =+G9/(1-J9) -> 0 | I9: =H9-G9 -> 0 | J9: 0
B10: Logistica y transporte | C10: 1 | D10: UND | E10: =+F10/C10 -> 252472.5 | F10: =+H10 -> 252472.5 | G10: =SUM('MATRIZ VENTA'!E50:E52) -> 252472.5 | H10: =+G10/(1-J10) -> 252472.5 | I10: =H10-G10 -> 0 | J10: 0
E11: TOTAL ANTES DE IVA | F11: =SUM(F5:F10) -> 1163159.2 | G11: =SUM(G5:G10) -> 858553.52 | H11: =+F11 -> 1163159.2 | I11: =H11-G11 -> 304605.64 | J11: =IFERROR(I11/H11,"0%") -> 0.26187787
E12: IVA 19% | F12: =+F11*19% -> 221000.24 | H12: =+F12 -> 221000.24
E13: TOTAL IVA INCLUIDO | F13: =+F11+F12 -> 1384159.4

Sheet Hoja1
A1: Transporte | B1: 181651.25
A2: Precipitador | B2: 599364.09
A3: Ductos y rejilla | B3: 345729.54
B4: =SUM(B1:B3) -> 1126744.9 | C4: 1076321.2
